â˜… loaded: /workspace/graph-vae/gvae/models/graphvae_core.py
concurrent.futures.process._RemoteTraceback: 
"""
Traceback (most recent call last):
  File "/opt/conda/lib/python3.10/multiprocessing/queues.py", line 244, in _feed
    obj = _ForkingPickler.dumps(obj)
  File "/opt/conda/lib/python3.10/multiprocessing/reduction.py", line 51, in dumps
    cls(buf, protocol).dump(obj)
AttributeError: Can't pickle local object 'main.<locals>._eval'
"""

The above exception was the direct cause of the following exception:

Traceback (most recent call last):
  File "/opt/conda/lib/python3.10/runpy.py", line 196, in _run_module_as_main
    return _run_code(code, main_globals, None,
  File "/opt/conda/lib/python3.10/runpy.py", line 86, in _run_code
    exec(code, run_globals)
  File "/workspace/graph-vae/gvae/eval/eval_stable.py", line 157, in <module>
    main()
  File "/workspace/graph-vae/gvae/eval/eval_stable.py", line 147, in main
    result_txt = fut.result()
  File "/opt/conda/lib/python3.10/concurrent/futures/_base.py", line 451, in result
    return self.__get_result()
  File "/opt/conda/lib/python3.10/concurrent/futures/_base.py", line 403, in __get_result
    raise self._exception
  File "/opt/conda/lib/python3.10/multiprocessing/queues.py", line 244, in _feed
    obj = _ForkingPickler.dumps(obj)
  File "/opt/conda/lib/python3.10/multiprocessing/reduction.py", line 51, in dumps
    cls(buf, protocol).dump(obj)
AttributeError: Can't pickle local object 'main.<locals>._eval'
